test_del_contact.py::test_delete_some_contact FAILED                     [100%]
test_del_contact.py:4 (test_delete_some_contact)
0 != 1

Expected :1
Actual   :0
<Click to see difference>

app = <fixture.application.Application object at 0x000002622DDBAB60>

    def test_delete_some_contact(app):
        if app.contact.count() == 0:
            app.contact.create(Contact(firstname="created"))
        old_contacts = app.contact.get_contact_list()
        index = randrange(len(old_contacts))
        app.contact.delete_contact_by_index(index)
>       assert len(old_contacts) - 1 == app.contact.count()
E       assert (1 - 1) == 1
E        +  where 1 = len([125::created])
E        +  and   1 = <bound method ContactHelper.count of <fixture.contact.ContactHelper object at 0x000002622DDBBD90>>()
E        +    where <bound method ContactHelper.count of <fixture.contact.ContactHelper object at 0x000002622DDBBD90>> = <fixture.contact.ContactHelper object at 0x000002622DDBBD90>.count
E        +      where <fixture.contact.ContactHelper object at 0x000002622DDBBD90> = <fixture.application.Application object at 0x000002622DDBAB60>.contact

test_del_contact.py:11: AssertionError